<?xml version="1.0"?>
<robot name="mowbot" xmlns:xacro="http://www.ros.org/wiki/xacro">

  <!--
    Base Link (Chassis)
    This represents the main body of your robot. 
    For a tank-style robot, the chassis is often more rectangular to accommodate the tracks.

    You will need to measure:
    1. Length of the chassis (in meters).
    2. Width of the chassis (in meters) — this will likely include the width of the tracks.
    3. Height of the chassis from the ground (in meters).
  -->
  <link name="base_link">
    <visual>
      <geometry>
        <!-- Adjust the size of the box to match the chassis -->
        <box size="0.5 0.4 0.2"/> <!-- Length: 0.5m, Width: 0.4m (including tracks), Height: 0.2m -->
      </geometry>
      <!-- The origin represents the center of the robot relative to the ground -->
      <origin xyz="0 0 0.1" rpy="0 0 0"/> <!-- Center the robot 0.1 meters above the ground -->
      <material name="gray"/>
    </visual>
    <collision>
      <geometry>
        <box size="0.5 0.4 0.2"/>
      </geometry>
      <origin xyz="0 0 0.1" rpy="0 0 0"/>
    </collision>
    <inertial>
      <mass value="8.0"/> <!-- Adjust mass to match the actual weight of your tracked chassis -->
      <origin xyz="0 0 0.1"/>
      <inertia ixx="0.2" ixy="0.0" ixz="0.0" iyy="0.2" iyz="0.0" izz="0.2"/>
    </inertial>
  </link>

  <!--
    Track Links
    These represent the left and right tracks. 
    Unlike wheels, tracks are continuous belts, but we can still represent them as elongated shapes.

    For measurements:
    1. Track length (in meters) — the distance from front to back of the track.
    2. Track width (in meters).
    3. Position of the tracks relative to the chassis center — this will depend on how far out
       the tracks extend from the chassis, especially if they stick out to the side.
  -->

  <!-- Left Track -->
  <link name="left_track">
    <visual>
      <geometry>
        <!-- Represent the track as a long, thin box -->
        <box size="0.05 0.4 0.05"/> <!-- Length (front to back): 0.4m, Width: 0.05m, Height: 0.05m -->
      </geometry>
      <!-- Position the left track relative to the chassis center:
           -0.15 meters behind the center, 0.2 meters to the left, and 0.05 meters above ground -->
      <origin xyz="-0.15 0.2 0.05" rpy="0 0 0"/>
      <material name="black"/>
    </visual>
    <collision>
      <geometry>
        <box size="0.05 0.4 0.05"/>
      </geometry>
      <origin xyz="-0.15 0.2 0.05" rpy="0 0 0"/>
    </collision>
    <inertial>
      <mass value="1.0"/> <!-- Adjust mass to match the actual weight of the left track -->
      <origin xyz="-0.15 0.2 0.05"/>
      <inertia ixx="0.01" ixy="0.0" ixz="0.0" iyy="0.01" iyz="0.0" izz="0.01"/>
    </inertial>
  </link>

  <!-- Right Track -->
  <link name="right_track">
    <visual>
      <geometry>
        <!-- Right track dimensions should match the left track -->
        <box size="0.05 0.4 0.05"/>
      </geometry>
      <!-- Position the right track relative to the chassis center:
           -0.15 meters behind the center, -0.2 meters to the right, and 0.05 meters above ground -->
      <origin xyz="-0.15 -0.2 0.05" rpy="0 0 0"/>
      <material name="black"/>
    </visual>
    <collision>
      <geometry>
        <box size="0.05 0.4 0.05"/>
      </geometry>
      <origin xyz="-0.15 -0.2 0.05" rpy="0 0 0"/>
    </collision>
    <inertial>
      <mass value="1.0"/> <!-- Adjust mass to match the actual weight of the right track -->
      <origin xyz="-0.15 -0.2 0.05"/>
      <inertia ixx="0.01" ixy="0.0" ixz="0.0" iyy="0.01" iyz="0.0" izz="0.01"/>
    </inertial>
  </link>

  <!--
    Lidar Sensor
    This represents the RPLidar mounted on your robot.
    
    You will need to measure:
    1. Radius of the lidar (in meters). Most lidars are cylindrical.
    2. Height above the base_link at which the lidar is mounted (in meters).
       The origin of the lidar should match where it is physically placed on your robot.
  -->
  <link name="lidar_link">
    <visual>
      <geometry>
        <cylinder length="0.04" radius="0.05"/> <!-- Adjust to match the size of your lidar -->
      </geometry>
      <!-- The origin places the lidar 0.15 meters above the robot chassis -->
      <origin xyz="0 0 0.15" rpy="0 0 0"/> <!-- Adjust xyz for your lidar's actual mounting point -->
      <material name="black"/>
    </visual>
    <collision>
      <geometry>
        <cylinder length="0.04" radius="0.05"/>
      </geometry>
      <origin xyz="0 0 0.15" rpy="0 0 0"/>
    </collision>
  </link>

  <!--
    Joints
    For track-driven robots, we represent the movement of the tracks similarly to wheels, 
    even though the tracks are continuous. The tracks will rotate like wheels.

    We use continuous joints to control the movement of the tracks.
  -->

  <!-- Left Track Joint -->
  <joint name="left_track_joint" type="continuous">
    <parent link="base_link"/>
    <child link="left_track"/>
    <!-- Position where the left track is attached to the chassis -->
    <origin xyz="-0.15 0.2 0.05" rpy="0 0 0"/>
    <axis xyz="0 1 0"/> <!-- The track rotates around the y-axis (like a wheel) -->
  </joint>

  <!-- Right Track Joint -->
  <joint name="right_track_joint" type="continuous">
    <parent link="base_link"/>
    <child link="right_track"/>
    <origin xyz="-0.15 -0.2 0.05" rpy="0 0 0"/>
    <axis xyz="0 1 0"/> <!-- The track rotates around the y-axis (like a wheel) -->
  </joint>

  <!-- Lidar Joint (fixed) -->
  <joint name="lidar_joint" type="fixed">
    <parent link="base_link"/>
    <child link="lidar_link"/>
    <!-- Attach the lidar 0.15 meters above the chassis -->
    <origin xyz="0 0 0.15" rpy="0 0 0"/>
  </joint>

  <!--
    Transmissions
    For track-driven robots, we still define transmissions to control the motors 
    that drive the left and right tracks.
  -->

  <!-- Transmission for Left Track -->
  <transmission name="left_track_transmission" type="SimpleTransmission">
    <actuator name="left_motor"/>
    <joint name="left_track_joint"/>
    <mechanicalReduction>1.0</mechanicalReduction> <!-- Modify if necessary based on gear ratio -->
  </transmission>

  <!-- Transmission for Right Track -->
  <transmission name="right_track_transmission" type="SimpleTransmission">
    <actuator name="right_motor"/>
    <joint name="right_track_joint"/>
    <mechanicalReduction>1.0</mechanicalReduction> <!-- Modify if necessary based on gear ratio -->
  </transmission>

</robot>
